[
  {
    "Timestamp": "2025-10-08T17:00:14+07:00",
    "Message": "Failed to call external API.",
    "Level": "Error",
    "Source": "Datadog",
    "TraceId": "AwAAAZnExCv6Fi89sAAAABhBWm5FeERFaEFBQzRRYzJnY2FzSDBRQUUAAAAkMTE5OWM1NjgtYmEyMS00YmM2LWEyOWMtMWMyYzg2NDhlZTM3AAABpQ",
    "FullLog": "{\u0022id\u0022:\u0022AwAAAZnExCv6Fi89sAAAABhBWm5FeERFaEFBQzRRYzJnY2FzSDBRQUUAAAAkMTE5OWM1NjgtYmEyMS00YmM2LWEyOWMtMWMyYzg2NDhlZTM3AAABpQ\u0022,\u0022type\u0022:\u0022log\u0022,\u0022attributes\u0022:{\u0022service\u0022:\u0022oopsAIConsoleTest\u0022,\u0022host\u0022:\u0022oopsAI\u0022,\u0022attributes\u0022:{\u0022MessageTemplate\u0022:\u0022Failed to call external API.\u0022,\u0022level\u0022:\u0022Error\u0022,\u0022service\u0022:\u0022oopsAIConsoleTest\u0022,\u0022host\u0022:\u0022oopsAI\u0022,\u0022Exception\u0022:\u0022System.Net.Http.HttpRequestException: Name or service not known (nonexistent.api.local:80)\\n ---\u003E System.Net.Sockets.SocketException (0xFFFDFFFF): Name or service not known\\n   at System.Net.Sockets.Socket.AwaitableSocketAsyncEventArgs.ThrowException(SocketError error, CancellationToken cancellationToken)\\n   at System.Net.Sockets.Socket.AwaitableSocketAsyncEventArgs.System.Threading.Tasks.Sources.IValueTaskSource.GetResult(Int16 token)\\n   at System.Net.Sockets.Socket.\u003CConnectAsync\u003Eg__WaitForConnectWithCancellation|285_0(AwaitableSocketAsyncEventArgs saea, ValueTask connectTask, CancellationToken cancellationToken)\\n   at System.Net.Http.HttpConnectionPool.ConnectToTcpHostAsync(String host, Int32 port, HttpRequestMessage initialRequest, Boolean async, CancellationToken cancellationToken)\\n   --- End of inner exception stack trace ---\\n   at System.Net.Http.HttpConnectionPool.ConnectToTcpHostAsync(String host, Int32 port, HttpRequestMessage initialRequest, Boolean async, CancellationToken cancellationToken)\\n   at System.Net.Http.HttpConnectionPool.ConnectAsync(HttpRequestMessage request, Boolean async, CancellationToken cancellationToken)\\n   at System.Net.Http.HttpConnectionPool.CreateHttp11ConnectionAsync(HttpRequestMessage request, Boolean async, CancellationToken cancellationToken)\\n   at System.Net.Http.HttpConnectionPool.AddHttp11ConnectionAsync(QueueItem queueItem)\\n   at System.Threading.Tasks.TaskCompletionSourceWithCancellation\u00601.WaitWithCancellationAsync(CancellationToken cancellationToken)\\n   at System.Net.Http.HttpConnectionPool.SendWithVersionDetectionAndRetryAsync(HttpRequestMessage request, Boolean async, Boolean doRequestAuth, CancellationToken cancellationToken)\\n   at System.Net.Http.DiagnosticsHandler.SendAsyncCore(HttpRequestMessage request, Boolean async, CancellationToken cancellationToken)\\n   at System.Net.Http.RedirectHandler.SendAsync(HttpRequestMessage request, Boolean async, CancellationToken cancellationToken)\\n   at System.Net.Http.HttpClient.\u003CSendAsync\u003Eg__Core|83_0(HttpRequestMessage request, HttpCompletionOption completionOption, CancellationTokenSource cts, Boolean disposeCts, CancellationTokenSource pendingRequestsCts, CancellationToken originalCancellationToken)\\n   at FakeDatadogApi.ErrorLogSimulator.SimulateHttpRequestError() in D:\\\\projects\\\\OppsAI\\\\Applications\\\\FakeDatadogApi\\\\ErrorLogSimulator.cs:line 218\u0022,\u0022timestamp\u0022:\u00222025-10-09T00:00:14.714847\u002B07:00\u0022},\u0022message\u0022:\u0022Failed to call external API.\u0022,\u0022status\u0022:\u0022error\u0022,\u0022timestamp\u0022:\u00222025-10-08T17:00:14.714Z\u0022,\u0022tags\u0022:[\u0022datadog.submission_auth:api_key\u0022,\u0022env:production\u0022,\u0022source:oopsai\u0022,\u0022version:1.0\u0022]}}"
  },
  {
    "Timestamp": "2025-10-08T17:00:16+07:00",
    "Message": "Arithmetic error in calculation.",
    "Level": "Error",
    "Source": "Datadog",
    "TraceId": "AwAAAZnExDNgvleHNwAAABhBWm5FeERtZkFBQlZtSndiOE1vclBnQUIAAAAkMTE5OWM1NjgtYmEyMS00YmM2LWEyOWMtMWMyYzg2NDhlZTM3AAABpA",
    "FullLog": "{\u0022id\u0022:\u0022AwAAAZnExDNgvleHNwAAABhBWm5FeERtZkFBQlZtSndiOE1vclBnQUIAAAAkMTE5OWM1NjgtYmEyMS00YmM2LWEyOWMtMWMyYzg2NDhlZTM3AAABpA\u0022,\u0022type\u0022:\u0022log\u0022,\u0022attributes\u0022:{\u0022service\u0022:\u0022oopsAIConsoleTest\u0022,\u0022host\u0022:\u0022oopsAI\u0022,\u0022attributes\u0022:{\u0022MessageTemplate\u0022:\u0022Arithmetic error in calculation.\u0022,\u0022level\u0022:\u0022Error\u0022,\u0022service\u0022:\u0022oopsAIConsoleTest\u0022,\u0022host\u0022:\u0022oopsAI\u0022,\u0022Exception\u0022:\u0022System.DivideByZeroException: Attempted to divide by zero.\\n   at FakeDatadogApi.ErrorLogSimulator.SimulateDivideByZeroError() in D:\\\\projects\\\\OppsAI\\\\Applications\\\\FakeDatadogApi\\\\ErrorLogSimulator.cs:line 99\u0022,\u0022timestamp\u0022:\u00222025-10-09T00:00:16.6085605\u002B07:00\u0022},\u0022message\u0022:\u0022Arithmetic error in calculation.\u0022,\u0022status\u0022:\u0022error\u0022,\u0022timestamp\u0022:\u00222025-10-08T17:00:16.608Z\u0022,\u0022tags\u0022:[\u0022datadog.submission_auth:api_key\u0022,\u0022env:production\u0022,\u0022source:oopsai\u0022,\u0022version:1.0\u0022]}}"
  },
  {
    "Timestamp": "2025-10-08T17:00:22+07:00",
    "Message": "Database connection string error.",
    "Level": "Error",
    "Source": "Datadog",
    "TraceId": "AwAAAZnExEnK-PP2UwAAABhBWm5FeEVwM0FBRGVKZF9zbG9Od013QUUAAAAkMTE5OWM1NjgtYmEyMS00YmM2LWEyOWMtMWMyYzg2NDhlZTM3AAABow",
    "FullLog": "{\u0022id\u0022:\u0022AwAAAZnExEnK-PP2UwAAABhBWm5FeEVwM0FBRGVKZF9zbG9Od013QUUAAAAkMTE5OWM1NjgtYmEyMS00YmM2LWEyOWMtMWMyYzg2NDhlZTM3AAABow\u0022,\u0022type\u0022:\u0022log\u0022,\u0022attributes\u0022:{\u0022service\u0022:\u0022oopsAIConsoleTest\u0022,\u0022host\u0022:\u0022oopsAI\u0022,\u0022attributes\u0022:{\u0022MessageTemplate\u0022:\u0022Database connection string error.\u0022,\u0022level\u0022:\u0022Error\u0022,\u0022service\u0022:\u0022oopsAIConsoleTest\u0022,\u0022host\u0022:\u0022oopsAI\u0022,\u0022Exception\u0022:\u0022System.InvalidOperationException: Invalid or missing database connection string.\\n   at FakeDatadogApi.ErrorLogSimulator.SimulateConnectionStringError(IConfiguration configuration) in D:\\\\projects\\\\OppsAI\\\\Applications\\\\FakeDatadogApi\\\\ErrorLogSimulator.cs:line 85\u0022,\u0022timestamp\u0022:\u00222025-10-09T00:00:22.3462367\u002B07:00\u0022},\u0022message\u0022:\u0022Database connection string error.\u0022,\u0022status\u0022:\u0022error\u0022,\u0022timestamp\u0022:\u00222025-10-08T17:00:22.346Z\u0022,\u0022tags\u0022:[\u0022datadog.submission_auth:api_key\u0022,\u0022env:production\u0022,\u0022source:oopsai\u0022,\u0022version:1.0\u0022]}}"
  },
  {
    "Timestamp": "2025-10-08T17:00:23+07:00",
    "Message": "Failed to read file due to FileNotFoundException.",
    "Level": "Error",
    "Source": "Datadog",
    "TraceId": "AwAAAZnExE826_zjPgAAABhBWm5FeEZMYkFBQm8xeFNLMnZlSjdnQUIAAAAkMTE5OWM1NjgtYmEyMS00YmM2LWEyOWMtMWMyYzg2NDhlZTM3AAABog",
    "FullLog": "{\u0022id\u0022:\u0022AwAAAZnExE826_zjPgAAABhBWm5FeEZMYkFBQm8xeFNLMnZlSjdnQUIAAAAkMTE5OWM1NjgtYmEyMS00YmM2LWEyOWMtMWMyYzg2NDhlZTM3AAABog\u0022,\u0022type\u0022:\u0022log\u0022,\u0022attributes\u0022:{\u0022service\u0022:\u0022oopsAIConsoleTest\u0022,\u0022host\u0022:\u0022oopsAI\u0022,\u0022attributes\u0022:{\u0022MessageTemplate\u0022:\u0022Failed to read file due to FileNotFoundException.\u0022,\u0022level\u0022:\u0022Error\u0022,\u0022service\u0022:\u0022oopsAIConsoleTest\u0022,\u0022host\u0022:\u0022oopsAI\u0022,\u0022Exception\u0022:\u0022System.IO.FileNotFoundException: Could not find file \u0027/home/site/wwwroot/nonexistent.txt\u0027.\\nFile name: \u0027/home/site/wwwroot/nonexistent.txt\u0027\\n   at Interop.ThrowExceptionForIoErrno(ErrorInfo errorInfo, String path, Boolean isDirError)\\n   at Microsoft.Win32.SafeHandles.SafeFileHandle.Open(String fullPath, FileMode mode, FileAccess access, FileShare share, FileOptions options, Int64 preallocationSize, UnixFileMode openPermissions, Int64\u0026 fileLength, UnixFileMode\u0026 filePermissions, Boolean failForSymlink, Boolean\u0026 wasSymlink, Func\u00604 createOpenException)\\n   at System.IO.Strategies.OSFileStreamStrategy..ctor(String path, FileMode mode, FileAccess access, FileShare share, FileOptions options, Int64 preallocationSize, Nullable\u00601 unixCreateMode)\\n   at System.IO.StreamReader.ValidateArgsAndOpenPath(String path, Encoding encoding, Int32 bufferSize)\\n   at System.IO.File.ReadAllText(String path, Encoding encoding)\\n   at FakeDatadogApi.ErrorLogSimulator.SimulateFileNotFoundError() in D:\\\\projects\\\\OppsAI\\\\Applications\\\\FakeDatadogApi\\\\ErrorLogSimulator.cs:line 111\u0022,\u0022timestamp\u0022:\u00222025-10-09T00:00:23.7341937\u002B07:00\u0022},\u0022message\u0022:\u0022Failed to read file due to FileNotFoundException.\u0022,\u0022status\u0022:\u0022error\u0022,\u0022timestamp\u0022:\u00222025-10-08T17:00:23.734Z\u0022,\u0022tags\u0022:[\u0022datadog.submission_auth:api_key\u0022,\u0022env:production\u0022,\u0022source:oopsai\u0022,\u0022version:1.0\u0022]}}"
  },
  {
    "Timestamp": "2025-10-08T17:00:24+07:00",
    "Message": "Custom application error occurred.",
    "Level": "Error",
    "Source": "Datadog",
    "TraceId": "AwAAAZnExFLrXxDR6gAAABhBWm5FeEZ0R0FBQzk3cjU0OHVoSTBRQUIAAAAkMTE5OWM1NjgtYmEyMS00YmM2LWEyOWMtMWMyYzg2NDhlZTM3AAABoQ",
    "FullLog": "{\u0022id\u0022:\u0022AwAAAZnExFLrXxDR6gAAABhBWm5FeEZ0R0FBQzk3cjU0OHVoSTBRQUIAAAAkMTE5OWM1NjgtYmEyMS00YmM2LWEyOWMtMWMyYzg2NDhlZTM3AAABoQ\u0022,\u0022type\u0022:\u0022log\u0022,\u0022attributes\u0022:{\u0022service\u0022:\u0022oopsAIConsoleTest\u0022,\u0022host\u0022:\u0022oopsAI\u0022,\u0022attributes\u0022:{\u0022MessageTemplate\u0022:\u0022Custom application error occurred.\u0022,\u0022level\u0022:\u0022Error\u0022,\u0022service\u0022:\u0022oopsAIConsoleTest\u0022,\u0022host\u0022:\u0022oopsAI\u0022,\u0022Exception\u0022:\u0022System.ApplicationException: Custom business logic error: User quota exceeded.\\n   at FakeDatadogApi.ErrorLogSimulator.SimulateCustomAppError() in D:\\\\projects\\\\OppsAI\\\\Applications\\\\FakeDatadogApi\\\\ErrorLogSimulator.cs:line 230\u0022,\u0022timestamp\u0022:\u00222025-10-09T00:00:24.6831638\u002B07:00\u0022},\u0022message\u0022:\u0022Custom application error occurred.\u0022,\u0022status\u0022:\u0022error\u0022,\u0022timestamp\u0022:\u00222025-10-08T17:00:24.683Z\u0022,\u0022tags\u0022:[\u0022datadog.submission_auth:api_key\u0022,\u0022env:production\u0022,\u0022source:oopsai\u0022,\u0022version:1.0\u0022]}}"
  },
  {
    "Timestamp": "2025-10-08T17:00:35+07:00",
    "Message": "Failed to read file due to FileNotFoundException.",
    "Level": "Error",
    "Source": "Datadog",
    "TraceId": "AwAAAZnExH5Wc4o8-AAAABhBWm5FeElZMUFBQ1BkZHRTTUlObW1nQUIAAAAkMTE5OWM1NjgtYmEyMS00YmM2LWEyOWMtMWMyYzg2NDhlZTM3AAABoA",
    "FullLog": "{\u0022id\u0022:\u0022AwAAAZnExH5Wc4o8-AAAABhBWm5FeElZMUFBQ1BkZHRTTUlObW1nQUIAAAAkMTE5OWM1NjgtYmEyMS00YmM2LWEyOWMtMWMyYzg2NDhlZTM3AAABoA\u0022,\u0022type\u0022:\u0022log\u0022,\u0022attributes\u0022:{\u0022service\u0022:\u0022oopsAIConsoleTest\u0022,\u0022host\u0022:\u0022oopsAI\u0022,\u0022attributes\u0022:{\u0022MessageTemplate\u0022:\u0022Failed to read file due to FileNotFoundException.\u0022,\u0022level\u0022:\u0022Error\u0022,\u0022service\u0022:\u0022oopsAIConsoleTest\u0022,\u0022host\u0022:\u0022oopsAI\u0022,\u0022Exception\u0022:\u0022System.IO.FileNotFoundException: Could not find file \u0027/home/site/wwwroot/nonexistent.txt\u0027.\\nFile name: \u0027/home/site/wwwroot/nonexistent.txt\u0027\\n   at Interop.ThrowExceptionForIoErrno(ErrorInfo errorInfo, String path, Boolean isDirError)\\n   at Microsoft.Win32.SafeHandles.SafeFileHandle.Open(String fullPath, FileMode mode, FileAccess access, FileShare share, FileOptions options, Int64 preallocationSize, UnixFileMode openPermissions, Int64\u0026 fileLength, UnixFileMode\u0026 filePermissions, Boolean failForSymlink, Boolean\u0026 wasSymlink, Func\u00604 createOpenException)\\n   at System.IO.Strategies.OSFileStreamStrategy..ctor(String path, FileMode mode, FileAccess access, FileShare share, FileOptions options, Int64 preallocationSize, Nullable\u00601 unixCreateMode)\\n   at System.IO.StreamReader.ValidateArgsAndOpenPath(String path, Encoding encoding, Int32 bufferSize)\\n   at System.IO.File.ReadAllText(String path, Encoding encoding)\\n   at FakeDatadogApi.ErrorLogSimulator.SimulateFileNotFoundError() in D:\\\\projects\\\\OppsAI\\\\Applications\\\\FakeDatadogApi\\\\ErrorLogSimulator.cs:line 111\u0022,\u0022timestamp\u0022:\u00222025-10-09T00:00:35.7981507\u002B07:00\u0022},\u0022message\u0022:\u0022Failed to read file due to FileNotFoundException.\u0022,\u0022status\u0022:\u0022error\u0022,\u0022timestamp\u0022:\u00222025-10-08T17:00:35.798Z\u0022,\u0022tags\u0022:[\u0022datadog.submission_auth:api_key\u0022,\u0022env:production\u0022,\u0022source:oopsai\u0022,\u0022version:1.0\u0022]}}"
  },
  {
    "Timestamp": "2025-10-08T17:00:36+07:00",
    "Message": "Invalid argument provided.",
    "Level": "Error",
    "Source": "Datadog",
    "TraceId": "AwAAAZnExIC8c4o8-gAAABhBWm5FeElZMUFBQ1BkZHRTTUlObW1nQUQAAAAkMTE5OWM1NjgtYmEyMS00YmM2LWEyOWMtMWMyYzg2NDhlZTM3AAABnw",
    "FullLog": "{\u0022id\u0022:\u0022AwAAAZnExIC8c4o8-gAAABhBWm5FeElZMUFBQ1BkZHRTTUlObW1nQUQAAAAkMTE5OWM1NjgtYmEyMS00YmM2LWEyOWMtMWMyYzg2NDhlZTM3AAABnw\u0022,\u0022type\u0022:\u0022log\u0022,\u0022attributes\u0022:{\u0022service\u0022:\u0022oopsAIConsoleTest\u0022,\u0022host\u0022:\u0022oopsAI\u0022,\u0022attributes\u0022:{\u0022MessageTemplate\u0022:\u0022Invalid argument provided.\u0022,\u0022level\u0022:\u0022Error\u0022,\u0022service\u0022:\u0022oopsAIConsoleTest\u0022,\u0022host\u0022:\u0022oopsAI\u0022,\u0022Exception\u0022:\u0022System.ArgumentException: Input parameter cannot be empty. (Parameter \u0027invalidInput\u0027)\\n   at FakeDatadogApi.ErrorLogSimulator.SimulateArgumentError() in D:\\\\projects\\\\OppsAI\\\\Applications\\\\FakeDatadogApi\\\\ErrorLogSimulator.cs:line 150\u0022,\u0022timestamp\u0022:\u00222025-10-09T00:00:36.4121257\u002B07:00\u0022},\u0022message\u0022:\u0022Invalid argument provided.\u0022,\u0022status\u0022:\u0022error\u0022,\u0022timestamp\u0022:\u00222025-10-08T17:00:36.412Z\u0022,\u0022tags\u0022:[\u0022datadog.submission_auth:api_key\u0022,\u0022env:production\u0022,\u0022source:oopsai\u0022,\u0022version:1.0\u0022]}}"
  },
  {
    "Timestamp": "2025-10-08T17:01:08+07:00",
    "Message": "Failed to read file due to FileNotFoundException.",
    "Level": "Error",
    "Source": "Datadog",
    "TraceId": "AwAAAZnExP6r6nCANwAAABhBWm5FeFFRaEFBQkdzM2ZONFJleGdBQUIAAAAkMTE5OWM1NjgtYmEyMS00YmM2LWEyOWMtMWMyYzg2NDhlZTM3AAABng",
    "FullLog": "{\u0022id\u0022:\u0022AwAAAZnExP6r6nCANwAAABhBWm5FeFFRaEFBQkdzM2ZONFJleGdBQUIAAAAkMTE5OWM1NjgtYmEyMS00YmM2LWEyOWMtMWMyYzg2NDhlZTM3AAABng\u0022,\u0022type\u0022:\u0022log\u0022,\u0022attributes\u0022:{\u0022service\u0022:\u0022oopsAIConsoleTest\u0022,\u0022host\u0022:\u0022oopsAI\u0022,\u0022attributes\u0022:{\u0022MessageTemplate\u0022:\u0022Failed to read file due to FileNotFoundException.\u0022,\u0022level\u0022:\u0022Error\u0022,\u0022service\u0022:\u0022oopsAIConsoleTest\u0022,\u0022host\u0022:\u0022oopsAI\u0022,\u0022Exception\u0022:\u0022System.IO.FileNotFoundException: Could not find file \u0027/home/site/wwwroot/nonexistent.txt\u0027.\\nFile name: \u0027/home/site/wwwroot/nonexistent.txt\u0027\\n   at Interop.ThrowExceptionForIoErrno(ErrorInfo errorInfo, String path, Boolean isDirError)\\n   at Microsoft.Win32.SafeHandles.SafeFileHandle.Open(String fullPath, FileMode mode, FileAccess access, FileShare share, FileOptions options, Int64 preallocationSize, UnixFileMode openPermissions, Int64\u0026 fileLength, UnixFileMode\u0026 filePermissions, Boolean failForSymlink, Boolean\u0026 wasSymlink, Func\u00604 createOpenException)\\n   at System.IO.Strategies.OSFileStreamStrategy..ctor(String path, FileMode mode, FileAccess access, FileShare share, FileOptions options, Int64 preallocationSize, Nullable\u00601 unixCreateMode)\\n   at System.IO.StreamReader.ValidateArgsAndOpenPath(String path, Encoding encoding, Int32 bufferSize)\\n   at System.IO.File.ReadAllText(String path, Encoding encoding)\\n   at FakeDatadogApi.ErrorLogSimulator.SimulateFileNotFoundError() in D:\\\\projects\\\\OppsAI\\\\Applications\\\\FakeDatadogApi\\\\ErrorLogSimulator.cs:line 111\u0022,\u0022timestamp\u0022:\u00222025-10-09T00:01:08.6510265\u002B07:00\u0022},\u0022message\u0022:\u0022Failed to read file due to FileNotFoundException.\u0022,\u0022status\u0022:\u0022error\u0022,\u0022timestamp\u0022:\u00222025-10-08T17:01:08.651Z\u0022,\u0022tags\u0022:[\u0022datadog.submission_auth:api_key\u0022,\u0022env:production\u0022,\u0022source:oopsai\u0022,\u0022version:1.0\u0022]}}"
  },
  {
    "Timestamp": "2025-10-08T17:02:07+07:00",
    "Message": "Timeout error during external service call.",
    "Level": "Error",
    "Source": "Datadog",
    "TraceId": "AwAAAZnExeKmiICrtgAAABhBWm5FeGVlcUFBRGRqcHdhN2Z0ZVJBQUUAAAAkMTE5OWM1NjgtYmEyMS00YmM2LWEyOWMtMWMyYzg2NDhlZTM3AAABnQ",
    "FullLog": "{\u0022id\u0022:\u0022AwAAAZnExeKmiICrtgAAABhBWm5FeGVlcUFBRGRqcHdhN2Z0ZVJBQUUAAAAkMTE5OWM1NjgtYmEyMS00YmM2LWEyOWMtMWMyYzg2NDhlZTM3AAABnQ\u0022,\u0022type\u0022:\u0022log\u0022,\u0022attributes\u0022:{\u0022service\u0022:\u0022oopsAIConsoleTest\u0022,\u0022host\u0022:\u0022oopsAI\u0022,\u0022attributes\u0022:{\u0022MessageTemplate\u0022:\u0022Timeout error during external service call.\u0022,\u0022level\u0022:\u0022Error\u0022,\u0022service\u0022:\u0022oopsAIConsoleTest\u0022,\u0022host\u0022:\u0022oopsAI\u0022,\u0022Exception\u0022:\u0022System.TimeoutException: Operation timed out while waiting for external service.\\n   at FakeDatadogApi.ErrorLogSimulator.SimulateTimeoutError() in D:\\\\projects\\\\OppsAI\\\\Applications\\\\FakeDatadogApi\\\\ErrorLogSimulator.cs:line 135\u0022,\u0022timestamp\u0022:\u00222025-10-09T00:02:07.0140869\u002B07:00\u0022},\u0022message\u0022:\u0022Timeout error during external service call.\u0022,\u0022status\u0022:\u0022error\u0022,\u0022timestamp\u0022:\u00222025-10-08T17:02:07.014Z\u0022,\u0022tags\u0022:[\u0022datadog.submission_auth:api_key\u0022,\u0022env:production\u0022,\u0022source:oopsai\u0022,\u0022version:1.0\u0022]}}"
  },
  {
    "Timestamp": "2025-10-08T17:03:06+07:00",
    "Message": "Custom application error occurred.",
    "Level": "Error",
    "Source": "Datadog",
    "TraceId": "AwAAAZnExsn-HQZtqQAAABhBWm5FeHM3ckFBQzZYVVhYbzA0RUpBQUIAAAAkMTE5OWM1NjgtYmEyMS00YmM2LWEyOWMtMWMyYzg2NDhlZTM3AAABnA",
    "FullLog": "{\u0022id\u0022:\u0022AwAAAZnExsn-HQZtqQAAABhBWm5FeHM3ckFBQzZYVVhYbzA0RUpBQUIAAAAkMTE5OWM1NjgtYmEyMS00YmM2LWEyOWMtMWMyYzg2NDhlZTM3AAABnA\u0022,\u0022type\u0022:\u0022log\u0022,\u0022attributes\u0022:{\u0022service\u0022:\u0022oopsAIConsoleTest\u0022,\u0022host\u0022:\u0022oopsAI\u0022,\u0022attributes\u0022:{\u0022MessageTemplate\u0022:\u0022Custom application error occurred.\u0022,\u0022level\u0022:\u0022Error\u0022,\u0022service\u0022:\u0022oopsAIConsoleTest\u0022,\u0022host\u0022:\u0022oopsAI\u0022,\u0022Exception\u0022:\u0022System.ApplicationException: Custom business logic error: User quota exceeded.\\n   at FakeDatadogApi.ErrorLogSimulator.SimulateCustomAppError() in D:\\\\projects\\\\OppsAI\\\\Applications\\\\FakeDatadogApi\\\\ErrorLogSimulator.cs:line 230\u0022,\u0022timestamp\u0022:\u00222025-10-09T00:03:06.2388762\u002B07:00\u0022},\u0022message\u0022:\u0022Custom application error occurred.\u0022,\u0022status\u0022:\u0022error\u0022,\u0022timestamp\u0022:\u00222025-10-08T17:03:06.238Z\u0022,\u0022tags\u0022:[\u0022datadog.submission_auth:api_key\u0022,\u0022env:production\u0022,\u0022source:oopsai\u0022,\u0022version:1.0\u0022]}}"
  },
  {
    "Timestamp": "2025-10-08T17:03:07+07:00",
    "Message": "Failed to read file due to FileNotFoundException.",
    "Level": "Error",
    "Source": "Datadog",
    "TraceId": "AwAAAZnExs61B906LwAAABhBWm5FeHRmUUFBQWRlU3k1Tk9qcVhRQUIAAAAkMTE5OWM1NjgtYmEyMS00YmM2LWEyOWMtMWMyYzg2NDhlZTM3AAABmw",
    "FullLog": "{\u0022id\u0022:\u0022AwAAAZnExs61B906LwAAABhBWm5FeHRmUUFBQWRlU3k1Tk9qcVhRQUIAAAAkMTE5OWM1NjgtYmEyMS00YmM2LWEyOWMtMWMyYzg2NDhlZTM3AAABmw\u0022,\u0022type\u0022:\u0022log\u0022,\u0022attributes\u0022:{\u0022service\u0022:\u0022oopsAIConsoleTest\u0022,\u0022host\u0022:\u0022oopsAI\u0022,\u0022attributes\u0022:{\u0022MessageTemplate\u0022:\u0022Failed to read file due to FileNotFoundException.\u0022,\u0022level\u0022:\u0022Error\u0022,\u0022service\u0022:\u0022oopsAIConsoleTest\u0022,\u0022host\u0022:\u0022oopsAI\u0022,\u0022Exception\u0022:\u0022System.IO.FileNotFoundException: Could not find file \u0027/home/site/wwwroot/nonexistent.txt\u0027.\\nFile name: \u0027/home/site/wwwroot/nonexistent.txt\u0027\\n   at Interop.ThrowExceptionForIoErrno(ErrorInfo errorInfo, String path, Boolean isDirError)\\n   at Microsoft.Win32.SafeHandles.SafeFileHandle.Open(String fullPath, FileMode mode, FileAccess access, FileShare share, FileOptions options, Int64 preallocationSize, UnixFileMode openPermissions, Int64\u0026 fileLength, UnixFileMode\u0026 filePermissions, Boolean failForSymlink, Boolean\u0026 wasSymlink, Func\u00604 createOpenException)\\n   at System.IO.Strategies.OSFileStreamStrategy..ctor(String path, FileMode mode, FileAccess access, FileShare share, FileOptions options, Int64 preallocationSize, Nullable\u00601 unixCreateMode)\\n   at System.IO.StreamReader.ValidateArgsAndOpenPath(String path, Encoding encoding, Int32 bufferSize)\\n   at System.IO.File.ReadAllText(String path, Encoding encoding)\\n   at FakeDatadogApi.ErrorLogSimulator.SimulateFileNotFoundError() in D:\\\\projects\\\\OppsAI\\\\Applications\\\\FakeDatadogApi\\\\ErrorLogSimulator.cs:line 111\u0022,\u0022timestamp\u0022:\u00222025-10-09T00:03:07.4459772\u002B07:00\u0022},\u0022message\u0022:\u0022Failed to read file due to FileNotFoundException.\u0022,\u0022status\u0022:\u0022error\u0022,\u0022timestamp\u0022:\u00222025-10-08T17:03:07.445Z\u0022,\u0022tags\u0022:[\u0022datadog.submission_auth:api_key\u0022,\u0022env:production\u0022,\u0022source:oopsai\u0022,\u0022version:1.0\u0022]}}"
  },
  {
    "Timestamp": "2025-10-08T17:03:50+07:00",
    "Message": "Key not found in dictionary.",
    "Level": "Error",
    "Source": "Datadog",
    "TraceId": "AwAAAZnEx3beHKf2OwAAABhBWm5FeDNpRkFBQncwNVZTZGh2MVNRQUUAAAAkMTE5OWM1NjgtYmEyMS00YmM2LWEyOWMtMWMyYzg2NDhlZTM3AAABmg",
    "FullLog": "{\u0022id\u0022:\u0022AwAAAZnEx3beHKf2OwAAABhBWm5FeDNpRkFBQncwNVZTZGh2MVNRQUUAAAAkMTE5OWM1NjgtYmEyMS00YmM2LWEyOWMtMWMyYzg2NDhlZTM3AAABmg\u0022,\u0022type\u0022:\u0022log\u0022,\u0022attributes\u0022:{\u0022service\u0022:\u0022oopsAIConsoleTest\u0022,\u0022host\u0022:\u0022oopsAI\u0022,\u0022attributes\u0022:{\u0022MessageTemplate\u0022:\u0022Key not found in dictionary.\u0022,\u0022level\u0022:\u0022Error\u0022,\u0022service\u0022:\u0022oopsAIConsoleTest\u0022,\u0022host\u0022:\u0022oopsAI\u0022,\u0022Exception\u0022:\u0022System.Collections.Generic.KeyNotFoundException: The given key \u0027missing_key\u0027 was not present in the dictionary.\\n   at FakeDatadogApi.ErrorLogSimulator.SimulateKeyNotFoundError() in D:\\\\projects\\\\OppsAI\\\\Applications\\\\FakeDatadogApi\\\\ErrorLogSimulator.cs:line 176\u0022,\u0022timestamp\u0022:\u00222025-10-09T00:03:50.4947756\u002B07:00\u0022},\u0022message\u0022:\u0022Key not found in dictionary.\u0022,\u0022status\u0022:\u0022error\u0022,\u0022timestamp\u0022:\u00222025-10-08T17:03:50.494Z\u0022,\u0022tags\u0022:[\u0022datadog.submission_auth:api_key\u0022,\u0022env:production\u0022,\u0022source:oopsai\u0022,\u0022version:1.0\u0022]}}"
  },
  {
    "Timestamp": "2025-10-08T17:03:51+07:00",
    "Message": "Invalid argument provided.",
    "Level": "Error",
    "Source": "Datadog",
    "TraceId": "AwAAAZnEx3uJBaNuiwAAABhBWm5FeDREeEFBRGpycjN5TFNYU1VBQUIAAAAkMTE5OWM1NjgtYmEyMS00YmM2LWEyOWMtMWMyYzg2NDhlZTM3AAABmQ",
    "FullLog": "{\u0022id\u0022:\u0022AwAAAZnEx3uJBaNuiwAAABhBWm5FeDREeEFBRGpycjN5TFNYU1VBQUIAAAAkMTE5OWM1NjgtYmEyMS00YmM2LWEyOWMtMWMyYzg2NDhlZTM3AAABmQ\u0022,\u0022type\u0022:\u0022log\u0022,\u0022attributes\u0022:{\u0022service\u0022:\u0022oopsAIConsoleTest\u0022,\u0022host\u0022:\u0022oopsAI\u0022,\u0022attributes\u0022:{\u0022MessageTemplate\u0022:\u0022Invalid argument provided.\u0022,\u0022level\u0022:\u0022Error\u0022,\u0022service\u0022:\u0022oopsAIConsoleTest\u0022,\u0022host\u0022:\u0022oopsAI\u0022,\u0022Exception\u0022:\u0022System.ArgumentException: Input parameter cannot be empty. (Parameter \u0027invalidInput\u0027)\\n   at FakeDatadogApi.ErrorLogSimulator.SimulateArgumentError() in D:\\\\projects\\\\OppsAI\\\\Applications\\\\FakeDatadogApi\\\\ErrorLogSimulator.cs:line 150\u0022,\u0022timestamp\u0022:\u00222025-10-09T00:03:51.6893879\u002B07:00\u0022},\u0022message\u0022:\u0022Invalid argument provided.\u0022,\u0022status\u0022:\u0022error\u0022,\u0022timestamp\u0022:\u00222025-10-08T17:03:51.689Z\u0022,\u0022tags\u0022:[\u0022datadog.submission_auth:api_key\u0022,\u0022env:production\u0022,\u0022source:oopsai\u0022,\u0022version:1.0\u0022]}}"
  },
  {
    "Timestamp": "2025-10-08T17:03:52+07:00",
    "Message": "Failed to call external API.",
    "Level": "Error",
    "Source": "Datadog",
    "TraceId": "AwAAAZnEx35KBaNujQAAABhBWm5FeDREeEFBRGpycjN5TFNYU1VBQUQAAAAkMTE5OWM1NjgtYmEyMS00YmM2LWEyOWMtMWMyYzg2NDhlZTM3AAABmA",
    "FullLog": "{\u0022id\u0022:\u0022AwAAAZnEx35KBaNujQAAABhBWm5FeDREeEFBRGpycjN5TFNYU1VBQUQAAAAkMTE5OWM1NjgtYmEyMS00YmM2LWEyOWMtMWMyYzg2NDhlZTM3AAABmA\u0022,\u0022type\u0022:\u0022log\u0022,\u0022attributes\u0022:{\u0022service\u0022:\u0022oopsAIConsoleTest\u0022,\u0022host\u0022:\u0022oopsAI\u0022,\u0022attributes\u0022:{\u0022MessageTemplate\u0022:\u0022Failed to call external API.\u0022,\u0022level\u0022:\u0022Error\u0022,\u0022service\u0022:\u0022oopsAIConsoleTest\u0022,\u0022host\u0022:\u0022oopsAI\u0022,\u0022Exception\u0022:\u0022System.Net.Http.HttpRequestException: Name or service not known (nonexistent.api.local:80)\\n ---\u003E System.Net.Sockets.SocketException (0xFFFDFFFF): Name or service not known\\n   at System.Net.Sockets.Socket.AwaitableSocketAsyncEventArgs.ThrowException(SocketError error, CancellationToken cancellationToken)\\n   at System.Net.Sockets.Socket.AwaitableSocketAsyncEventArgs.System.Threading.Tasks.Sources.IValueTaskSource.GetResult(Int16 token)\\n   at System.Net.Sockets.Socket.\u003CConnectAsync\u003Eg__WaitForConnectWithCancellation|285_0(AwaitableSocketAsyncEventArgs saea, ValueTask connectTask, CancellationToken cancellationToken)\\n   at System.Net.Http.HttpConnectionPool.ConnectToTcpHostAsync(String host, Int32 port, HttpRequestMessage initialRequest, Boolean async, CancellationToken cancellationToken)\\n   --- End of inner exception stack trace ---\\n   at System.Net.Http.HttpConnectionPool.ConnectToTcpHostAsync(String host, Int32 port, HttpRequestMessage initialRequest, Boolean async, CancellationToken cancellationToken)\\n   at System.Net.Http.HttpConnectionPool.ConnectAsync(HttpRequestMessage request, Boolean async, CancellationToken cancellationToken)\\n   at System.Net.Http.HttpConnectionPool.CreateHttp11ConnectionAsync(HttpRequestMessage request, Boolean async, CancellationToken cancellationToken)\\n   at System.Net.Http.HttpConnectionPool.AddHttp11ConnectionAsync(QueueItem queueItem)\\n   at System.Threading.Tasks.TaskCompletionSourceWithCancellation\u00601.WaitWithCancellationAsync(CancellationToken cancellationToken)\\n   at System.Net.Http.HttpConnectionPool.SendWithVersionDetectionAndRetryAsync(HttpRequestMessage request, Boolean async, Boolean doRequestAuth, CancellationToken cancellationToken)\\n   at System.Net.Http.DiagnosticsHandler.SendAsyncCore(HttpRequestMessage request, Boolean async, CancellationToken cancellationToken)\\n   at System.Net.Http.RedirectHandler.SendAsync(HttpRequestMessage request, Boolean async, CancellationToken cancellationToken)\\n   at System.Net.Http.HttpClient.\u003CSendAsync\u003Eg__Core|83_0(HttpRequestMessage request, HttpCompletionOption completionOption, CancellationTokenSource cts, Boolean disposeCts, CancellationTokenSource pendingRequestsCts, CancellationToken originalCancellationToken)\\n   at FakeDatadogApi.ErrorLogSimulator.SimulateHttpRequestError() in D:\\\\projects\\\\OppsAI\\\\Applications\\\\FakeDatadogApi\\\\ErrorLogSimulator.cs:line 218\u0022,\u0022timestamp\u0022:\u00222025-10-09T00:03:52.3941494\u002B07:00\u0022},\u0022message\u0022:\u0022Failed to call external API.\u0022,\u0022status\u0022:\u0022error\u0022,\u0022timestamp\u0022:\u00222025-10-08T17:03:52.394Z\u0022,\u0022tags\u0022:[\u0022datadog.submission_auth:api_key\u0022,\u0022env:production\u0022,\u0022source:oopsai\u0022,\u0022version:1.0\u0022]}}"
  },
  {
    "Timestamp": "2025-10-08T17:04:17+07:00",
    "Message": "Failed to read file due to FileNotFoundException.",
    "Level": "Error",
    "Source": "Datadog",
    "TraceId": "AwAAAZnEx99BpOSwLAAAABhBWm5FeC1Xc0FBREFRcFpZbHZZNmJnQUIAAAAkMTE5OWM1NjgtYmEyMS00YmM2LWEyOWMtMWMyYzg2NDhlZTM3AAABlw",
    "FullLog": "{\u0022id\u0022:\u0022AwAAAZnEx99BpOSwLAAAABhBWm5FeC1Xc0FBREFRcFpZbHZZNmJnQUIAAAAkMTE5OWM1NjgtYmEyMS00YmM2LWEyOWMtMWMyYzg2NDhlZTM3AAABlw\u0022,\u0022type\u0022:\u0022log\u0022,\u0022attributes\u0022:{\u0022service\u0022:\u0022oopsAIConsoleTest\u0022,\u0022host\u0022:\u0022oopsAI\u0022,\u0022attributes\u0022:{\u0022MessageTemplate\u0022:\u0022Failed to read file due to FileNotFoundException.\u0022,\u0022level\u0022:\u0022Error\u0022,\u0022service\u0022:\u0022oopsAIConsoleTest\u0022,\u0022host\u0022:\u0022oopsAI\u0022,\u0022Exception\u0022:\u0022System.IO.FileNotFoundException: Could not find file \u0027/home/site/wwwroot/nonexistent.txt\u0027.\\nFile name: \u0027/home/site/wwwroot/nonexistent.txt\u0027\\n   at Interop.ThrowExceptionForIoErrno(ErrorInfo errorInfo, String path, Boolean isDirError)\\n   at Microsoft.Win32.SafeHandles.SafeFileHandle.Open(String fullPath, FileMode mode, FileAccess access, FileShare share, FileOptions options, Int64 preallocationSize, UnixFileMode openPermissions, Int64\u0026 fileLength, UnixFileMode\u0026 filePermissions, Boolean failForSymlink, Boolean\u0026 wasSymlink, Func\u00604 createOpenException)\\n   at System.IO.Strategies.OSFileStreamStrategy..ctor(String path, FileMode mode, FileAccess access, FileShare share, FileOptions options, Int64 preallocationSize, Nullable\u00601 unixCreateMode)\\n   at System.IO.StreamReader.ValidateArgsAndOpenPath(String path, Encoding encoding, Int32 bufferSize)\\n   at System.IO.File.ReadAllText(String path, Encoding encoding)\\n   at FakeDatadogApi.ErrorLogSimulator.SimulateFileNotFoundError() in D:\\\\projects\\\\OppsAI\\\\Applications\\\\FakeDatadogApi\\\\ErrorLogSimulator.cs:line 111\u0022,\u0022timestamp\u0022:\u00222025-10-09T00:04:17.2177274\u002B07:00\u0022},\u0022message\u0022:\u0022Failed to read file due to FileNotFoundException.\u0022,\u0022status\u0022:\u0022error\u0022,\u0022timestamp\u0022:\u00222025-10-08T17:04:17.217Z\u0022,\u0022tags\u0022:[\u0022datadog.submission_auth:api_key\u0022,\u0022env:production\u0022,\u0022source:oopsai\u0022,\u0022version:1.0\u0022]}}"
  },
  {
    "Timestamp": "2025-10-08T17:04:17+07:00",
    "Message": "Key not found in dictionary.",
    "Level": "Error",
    "Source": "Datadog",
    "TraceId": "AwAAAZnEx-F7pOSwLgAAABhBWm5FeC1Xc0FBREFRcFpZbHZZNmJnQUQAAAAkMTE5OWM1NjgtYmEyMS00YmM2LWEyOWMtMWMyYzg2NDhlZTM3AAABlg",
    "FullLog": "{\u0022id\u0022:\u0022AwAAAZnEx-F7pOSwLgAAABhBWm5FeC1Xc0FBREFRcFpZbHZZNmJnQUQAAAAkMTE5OWM1NjgtYmEyMS00YmM2LWEyOWMtMWMyYzg2NDhlZTM3AAABlg\u0022,\u0022type\u0022:\u0022log\u0022,\u0022attributes\u0022:{\u0022service\u0022:\u0022oopsAIConsoleTest\u0022,\u0022host\u0022:\u0022oopsAI\u0022,\u0022attributes\u0022:{\u0022MessageTemplate\u0022:\u0022Key not found in dictionary.\u0022,\u0022level\u0022:\u0022Error\u0022,\u0022service\u0022:\u0022oopsAIConsoleTest\u0022,\u0022host\u0022:\u0022oopsAI\u0022,\u0022Exception\u0022:\u0022System.Collections.Generic.KeyNotFoundException: The given key \u0027missing_key\u0027 was not present in the dictionary.\\n   at FakeDatadogApi.ErrorLogSimulator.SimulateKeyNotFoundError() in D:\\\\projects\\\\OppsAI\\\\Applications\\\\FakeDatadogApi\\\\ErrorLogSimulator.cs:line 176\u0022,\u0022timestamp\u0022:\u00222025-10-09T00:04:17.7877747\u002B07:00\u0022},\u0022message\u0022:\u0022Key not found in dictionary.\u0022,\u0022status\u0022:\u0022error\u0022,\u0022timestamp\u0022:\u00222025-10-08T17:04:17.787Z\u0022,\u0022tags\u0022:[\u0022datadog.submission_auth:api_key\u0022,\u0022env:production\u0022,\u0022source:oopsai\u0022,\u0022version:1.0\u0022]}}"
  },
  {
    "Timestamp": "2025-10-08T17:04:19+07:00",
    "Message": "Timeout error during external service call.",
    "Level": "Error",
    "Source": "Datadog",
    "TraceId": "AwAAAZnEx-dYHY6FGAAAABhBWm5FeC0zOUFBQkVLOVBldEd3SFV3QUIAAAAkMTE5OWM1NjgtYmEyMS00YmM2LWEyOWMtMWMyYzg2NDhlZTM3AAABlQ",
    "FullLog": "{\u0022id\u0022:\u0022AwAAAZnEx-dYHY6FGAAAABhBWm5FeC0zOUFBQkVLOVBldEd3SFV3QUIAAAAkMTE5OWM1NjgtYmEyMS00YmM2LWEyOWMtMWMyYzg2NDhlZTM3AAABlQ\u0022,\u0022type\u0022:\u0022log\u0022,\u0022attributes\u0022:{\u0022service\u0022:\u0022oopsAIConsoleTest\u0022,\u0022host\u0022:\u0022oopsAI\u0022,\u0022attributes\u0022:{\u0022MessageTemplate\u0022:\u0022Timeout error during external service call.\u0022,\u0022level\u0022:\u0022Error\u0022,\u0022service\u0022:\u0022oopsAIConsoleTest\u0022,\u0022host\u0022:\u0022oopsAI\u0022,\u0022Exception\u0022:\u0022System.TimeoutException: Operation timed out while waiting for external service.\\n   at FakeDatadogApi.ErrorLogSimulator.SimulateTimeoutError() in D:\\\\projects\\\\OppsAI\\\\Applications\\\\FakeDatadogApi\\\\ErrorLogSimulator.cs:line 135\u0022,\u0022timestamp\u0022:\u00222025-10-09T00:04:19.2884886\u002B07:00\u0022},\u0022message\u0022:\u0022Timeout error during external service call.\u0022,\u0022status\u0022:\u0022error\u0022,\u0022timestamp\u0022:\u00222025-10-08T17:04:19.288Z\u0022,\u0022tags\u0022:[\u0022datadog.submission_auth:api_key\u0022,\u0022env:production\u0022,\u0022source:oopsai\u0022,\u0022version:1.0\u0022]}}"
  },
  {
    "Timestamp": "2025-10-08T17:04:43+07:00",
    "Message": "Database connection string error.",
    "Level": "Error",
    "Source": "Datadog",
    "TraceId": "AwAAAZnEyERhBgOLUwAAABhBWm5FeUVuZkFBQUxnWjBfRXZOMVR3QUUAAAAkMTE5OWM1NjgtYmEyMS00YmM2LWEyOWMtMWMyYzg2NDhlZTM3AAABlA",
    "FullLog": "{\u0022id\u0022:\u0022AwAAAZnEyERhBgOLUwAAABhBWm5FeUVuZkFBQUxnWjBfRXZOMVR3QUUAAAAkMTE5OWM1NjgtYmEyMS00YmM2LWEyOWMtMWMyYzg2NDhlZTM3AAABlA\u0022,\u0022type\u0022:\u0022log\u0022,\u0022attributes\u0022:{\u0022service\u0022:\u0022oopsAIConsoleTest\u0022,\u0022host\u0022:\u0022oopsAI\u0022,\u0022attributes\u0022:{\u0022MessageTemplate\u0022:\u0022Database connection string error.\u0022,\u0022level\u0022:\u0022Error\u0022,\u0022service\u0022:\u0022oopsAIConsoleTest\u0022,\u0022host\u0022:\u0022oopsAI\u0022,\u0022Exception\u0022:\u0022System.InvalidOperationException: Invalid or missing database connection string.\\n   at FakeDatadogApi.ErrorLogSimulator.SimulateConnectionStringError(IConfiguration configuration) in D:\\\\projects\\\\OppsAI\\\\Applications\\\\FakeDatadogApi\\\\ErrorLogSimulator.cs:line 85\u0022,\u0022timestamp\u0022:\u00222025-10-09T00:04:43.1050931\u002B07:00\u0022},\u0022message\u0022:\u0022Database connection string error.\u0022,\u0022status\u0022:\u0022error\u0022,\u0022timestamp\u0022:\u00222025-10-08T17:04:43.105Z\u0022,\u0022tags\u0022:[\u0022datadog.submission_auth:api_key\u0022,\u0022env:production\u0022,\u0022source:oopsai\u0022,\u0022version:1.0\u0022]}}"
  },
  {
    "Timestamp": "2025-10-08T17:04:43+07:00",
    "Message": "Failed to call external API.",
    "Level": "Error",
    "Source": "Datadog",
    "TraceId": "AwAAAZnEyEdFBgOLVQAAABhBWm5FeUVuZkFBQUxnWjBfRXZOMVR3QUcAAAAkMTE5OWM1NjgtYmEyMS00YmM2LWEyOWMtMWMyYzg2NDhlZTM3AAABkw",
    "FullLog": "{\u0022id\u0022:\u0022AwAAAZnEyEdFBgOLVQAAABhBWm5FeUVuZkFBQUxnWjBfRXZOMVR3QUcAAAAkMTE5OWM1NjgtYmEyMS00YmM2LWEyOWMtMWMyYzg2NDhlZTM3AAABkw\u0022,\u0022type\u0022:\u0022log\u0022,\u0022attributes\u0022:{\u0022service\u0022:\u0022oopsAIConsoleTest\u0022,\u0022host\u0022:\u0022oopsAI\u0022,\u0022attributes\u0022:{\u0022MessageTemplate\u0022:\u0022Failed to call external API.\u0022,\u0022level\u0022:\u0022Error\u0022,\u0022service\u0022:\u0022oopsAIConsoleTest\u0022,\u0022host\u0022:\u0022oopsAI\u0022,\u0022Exception\u0022:\u0022System.Net.Http.HttpRequestException: Name or service not known (nonexistent.api.local:80)\\n ---\u003E System.Net.Sockets.SocketException (0xFFFDFFFF): Name or service not known\\n   at System.Net.Sockets.Socket.AwaitableSocketAsyncEventArgs.ThrowException(SocketError error, CancellationToken cancellationToken)\\n   at System.Net.Sockets.Socket.AwaitableSocketAsyncEventArgs.System.Threading.Tasks.Sources.IValueTaskSource.GetResult(Int16 token)\\n   at System.Net.Sockets.Socket.\u003CConnectAsync\u003Eg__WaitForConnectWithCancellation|285_0(AwaitableSocketAsyncEventArgs saea, ValueTask connectTask, CancellationToken cancellationToken)\\n   at System.Net.Http.HttpConnectionPool.ConnectToTcpHostAsync(String host, Int32 port, HttpRequestMessage initialRequest, Boolean async, CancellationToken cancellationToken)\\n   --- End of inner exception stack trace ---\\n   at System.Net.Http.HttpConnectionPool.ConnectToTcpHostAsync(String host, Int32 port, HttpRequestMessage initialRequest, Boolean async, CancellationToken cancellationToken)\\n   at System.Net.Http.HttpConnectionPool.ConnectAsync(HttpRequestMessage request, Boolean async, CancellationToken cancellationToken)\\n   at System.Net.Http.HttpConnectionPool.CreateHttp11ConnectionAsync(HttpRequestMessage request, Boolean async, CancellationToken cancellationToken)\\n   at System.Net.Http.HttpConnectionPool.AddHttp11ConnectionAsync(QueueItem queueItem)\\n   at System.Threading.Tasks.TaskCompletionSourceWithCancellation\u00601.WaitWithCancellationAsync(CancellationToken cancellationToken)\\n   at System.Net.Http.HttpConnectionPool.SendWithVersionDetectionAndRetryAsync(HttpRequestMessage request, Boolean async, Boolean doRequestAuth, CancellationToken cancellationToken)\\n   at System.Net.Http.DiagnosticsHandler.SendAsyncCore(HttpRequestMessage request, Boolean async, CancellationToken cancellationToken)\\n   at System.Net.Http.RedirectHandler.SendAsync(HttpRequestMessage request, Boolean async, CancellationToken cancellationToken)\\n   at System.Net.Http.HttpClient.\u003CSendAsync\u003Eg__Core|83_0(HttpRequestMessage request, HttpCompletionOption completionOption, CancellationTokenSource cts, Boolean disposeCts, CancellationTokenSource pendingRequestsCts, CancellationToken originalCancellationToken)\\n   at FakeDatadogApi.ErrorLogSimulator.SimulateHttpRequestError() in D:\\\\projects\\\\OppsAI\\\\Applications\\\\FakeDatadogApi\\\\ErrorLogSimulator.cs:line 218\u0022,\u0022timestamp\u0022:\u00222025-10-09T00:04:43.845884\u002B07:00\u0022},\u0022message\u0022:\u0022Failed to call external API.\u0022,\u0022status\u0022:\u0022error\u0022,\u0022timestamp\u0022:\u00222025-10-08T17:04:43.845Z\u0022,\u0022tags\u0022:[\u0022datadog.submission_auth:api_key\u0022,\u0022env:production\u0022,\u0022source:oopsai\u0022,\u0022version:1.0\u0022]}}"
  },
  {
    "Timestamp": "2025-10-08T17:05:01+07:00",
    "Message": "Invalid cast operation.",
    "Level": "Error",
    "Source": "Datadog",
    "TraceId": "AwAAAZnEyI3PODvjQQAAABhBWm5FeUpSWEFBQm8xeFNLMmdEV0xRQUUAAAAkMTE5OWM1NjgtYmEyMS00YmM2LWEyOWMtMWMyYzg2NDhlZTM3AAABkg",
    "FullLog": "{\u0022id\u0022:\u0022AwAAAZnEyI3PODvjQQAAABhBWm5FeUpSWEFBQm8xeFNLMmdEV0xRQUUAAAAkMTE5OWM1NjgtYmEyMS00YmM2LWEyOWMtMWMyYzg2NDhlZTM3AAABkg\u0022,\u0022type\u0022:\u0022log\u0022,\u0022attributes\u0022:{\u0022service\u0022:\u0022oopsAIConsoleTest\u0022,\u0022host\u0022:\u0022oopsAI\u0022,\u0022attributes\u0022:{\u0022MessageTemplate\u0022:\u0022Invalid cast operation.\u0022,\u0022level\u0022:\u0022Error\u0022,\u0022service\u0022:\u0022oopsAIConsoleTest\u0022,\u0022host\u0022:\u0022oopsAI\u0022,\u0022Exception\u0022:\u0022System.InvalidCastException: Unable to cast object of type \u0027System.String\u0027 to type \u0027System.Int32\u0027.\\n   at FakeDatadogApi.ErrorLogSimulator.SimulateInvalidCastError() in D:\\\\projects\\\\OppsAI\\\\Applications\\\\FakeDatadogApi\\\\ErrorLogSimulator.cs:line 189\u0022,\u0022timestamp\u0022:\u00222025-10-09T00:05:01.9037511\u002B07:00\u0022},\u0022message\u0022:\u0022Invalid cast operation.\u0022,\u0022status\u0022:\u0022error\u0022,\u0022timestamp\u0022:\u00222025-10-08T17:05:01.903Z\u0022,\u0022tags\u0022:[\u0022datadog.submission_auth:api_key\u0022,\u0022env:production\u0022,\u0022source:oopsai\u0022,\u0022version:1.0\u0022]}}"
  }
]